<?xml version="1.0" encoding="utf-8"?>
<!-- This URDF was automatically created by SolidWorks to URDF Exporter! Originally created by Stephen Brawner (brawner@gmail.com) 
     Commit Version: 1.5.1-0-g916b5db  Build Version: 1.5.7152.31018
     For more information, please see http://wiki.ros.org/sw_urdf_exporter -->
<robot
  name="urdf_leg">
  <link
    name="base_link">
    <inertial>
      <origin
        xyz="0.20111 0.23366 0.30564"
        rpy="0 0 0" />
      <mass
        value="2.4018" />
      <inertia
        ixx="0.0070769"
        ixy="-2.7325E-07"
        ixz="1.9337E-07"
        iyy="0.015485"
        iyz="-1.2072E-07"
        izz="0.009591" />
    </inertial>
    <visual>
      <origin
        xyz="0 0 0"
        rpy="0 0 0" />
      <geometry>
        <mesh
          filename="package://urdf_leg/meshes/base_link.STL" />
      </geometry>
      <material
        name="">
        <color
          rgba="0.79216 0.81961 0.93333 1" />
      </material>
    </visual>
    <collision>
      <origin
        xyz="0 0 0"
        rpy="0 0 0" />
      <geometry>
        <mesh
          filename="package://urdf_leg/meshes/base_link.STL" />
      </geometry>
    </collision>
  </link>
  <link
    name="llink1">
    <inertial>
      <origin
        xyz="0.0307791868334724 -0.215484371552082 -1.10573228412347E-06"
        rpy="0 0 0" />
      <mass
        value="0.43136989307321" />
      <inertia
        ixx="0.00261255373009683"
        ixy="-1.54730224764238E-07"
        ixz="-5.4625490330409E-08"
        iyy="0.000204363979846619"
        iyz="-9.799960602793E-06"
        izz="0.00272660768895071" />
    </inertial>
    <visual>
      <origin
        xyz="0 0 0"
        rpy="0 0 0" />
      <geometry>
        <mesh
          filename="package://urdf_leg/meshes/llink1.STL" />
      </geometry>
      <material
        name="">
        <color
          rgba="0.792156862745098 0.819607843137255 0.933333333333333 1" />
      </material>
    </visual>
    <collision>
      <origin
        xyz="0 0 0"
        rpy="0 0 0" />
      <geometry>
        <mesh
          filename="package://urdf_leg/meshes/llink1.STL" />
      </geometry>
    </collision>
  </link>
  <joint
    name="ljoint1"
    type="continuous">
    <origin
      xyz="0 -0.26657 0.13336"
      rpy="1.5708 0 0" />
    <parent
      link="base_link" />
    <child
      link="llink1" />
    <axis
      xyz="1 0 0" />
  </joint>
  <link
    name="llink2">
    <inertial>
      <origin
        xyz="0.0291413196663437 -0.177961893333791 -0.00157862107611317"
        rpy="0 0 0" />
      <mass
        value="0.455413997264765" />
      <inertia
        ixx="0.0026249658638958"
        ixy="-5.35676102081581E-18"
        ixz="-3.99498195975885E-17"
        iyy="0.000232825591707952"
        iyz="4.91487669826942E-06"
        izz="0.00274374190170977" />
    </inertial>
    <visual>
      <origin
        xyz="0 0 0"
        rpy="0 0 0" />
      <geometry>
        <mesh
          filename="package://urdf_leg/meshes/llink2.STL" />
      </geometry>
      <material
        name="">
        <color
          rgba="0.792156862745098 0.819607843137255 0.933333333333333 1" />
      </material>
    </visual>
    <collision>
      <origin
        xyz="0 0 0"
        rpy="0 0 0" />
      <geometry>
        <mesh
          filename="package://urdf_leg/meshes/llink2.STL" />
      </geometry>
    </collision>
  </link>
  <joint
    name="ljoint2"
    type="continuous">
    <origin
      xyz="0 -0.438 0"
      rpy="0 0 0" />
    <parent
      link="llink1" />
    <child
      link="llink2" />
    <axis
      xyz="1 0 0" />
  </joint>
  <link
    name="llink3">
    <inertial>
      <origin
        xyz="0.0312440014766714 -0.0366754335013655 0.049330963427308"
        rpy="0 0 0" />
      <mass
        value="0.291189773826857" />
      <inertia
        ixx="0.000610485905391525"
        ixy="1.36625094874664E-07"
        ixz="-9.66829387673093E-08"
        iyy="0.000684347300419343"
        iyz="-6.0357579672748E-08"
        izz="0.000116061793166679" />
    </inertial>
    <visual>
      <origin
        xyz="0 0 0"
        rpy="0 0 0" />
      <geometry>
        <mesh
          filename="package://urdf_leg/meshes/llink3.STL" />
      </geometry>
      <material
        name="">
        <color
          rgba="0.792156862745098 0.819607843137255 0.933333333333333 1" />
      </material>
    </visual>
    <collision>
      <origin
        xyz="0 0 0"
        rpy="0 0 0" />
      <geometry>
        <mesh
          filename="package://urdf_leg/meshes/llink3.STL" />
      </geometry>
    </collision>
  </link>
  <joint
    name="ljoint3"
    type="continuous">
    <origin
      xyz="0 -0.44 0"
      rpy="0 0 0" />
    <parent
      link="llink2" />
    <child
      link="llink3" />
    <axis
      xyz="1 0 0" />
  </joint>
  <link
    name="rlink1">
    <inertial>
      <origin
        xyz="0.0560836371363365 -0.215484371552082 -1.10573228417898E-06"
        rpy="0 0 0" />
      <mass
        value="0.431369893073211" />
      <inertia
        ixx="0.00261255373009683"
        ixy="-1.54730224764526E-07"
        ixz="-5.46254903304758E-08"
        iyy="0.000204363979846619"
        iyz="-9.79996060279391E-06"
        izz="0.00272660768895072" />
    </inertial>
    <visual>
      <origin
        xyz="0 0 0"
        rpy="0 0 0" />
      <geometry>
        <mesh
          filename="package://urdf_leg/meshes/rlink1.STL" />
      </geometry>
      <material
        name="">
        <color
          rgba="0.792156862745098 0.819607843137255 0.933333333333333 1" />
      </material>
    </visual>
    <collision>
      <origin
        xyz="0 0 0"
        rpy="0 0 0" />
      <geometry>
        <mesh
          filename="package://urdf_leg/meshes/rlink1.STL" />
      </geometry>
    </collision>
  </link>
  <joint
    name="rjoint1"
    type="continuous">
    <origin
      xyz="0.3147 -0.26657 0.13336"
      rpy="1.5708 0 0" />
    <parent
      link="base_link" />
    <child
      link="rlink1" />
    <axis
      xyz="1 0 0" />
  </joint>
  <link
    name="rlink2">
    <inertial>
      <origin
        xyz="0.0544457699691987 -0.177961893333791 -0.00157862107611328"
        rpy="0 0 0" />
      <mass
        value="0.455413997264767" />
      <inertia
        ixx="0.00262496586389582"
        ixy="-5.41480015475625E-18"
        ixz="-4.00464306750793E-17"
        iyy="0.000232825591707953"
        iyz="4.91487669826903E-06"
        izz="0.00274374190170979" />
    </inertial>
    <visual>
      <origin
        xyz="0 0 0"
        rpy="0 0 0" />
      <geometry>
        <mesh
          filename="package://urdf_leg/meshes/rlink2.STL" />
      </geometry>
      <material
        name="">
        <color
          rgba="0.792156862745098 0.819607843137255 0.933333333333333 1" />
      </material>
    </visual>
    <collision>
      <origin
        xyz="0 0 0"
        rpy="0 0 0" />
      <geometry>
        <mesh
          filename="package://urdf_leg/meshes/rlink2.STL" />
      </geometry>
    </collision>
  </link>
  <joint
    name="rjoint2"
    type="continuous">
    <origin
      xyz="0 -0.438 0"
      rpy="0 0 0" />
    <parent
      link="rlink1" />
    <child
      link="rlink2" />
    <axis
      xyz="1 0 0" />
  </joint>
  <link
    name="rlink3">
    <inertial>
      <origin
        xyz="0.0491984517795272 -0.0366754335013657 0.0493309634273081"
        rpy="0 0 0" />
      <mass
        value="0.291189773826858" />
      <inertia
        ixx="0.000610485905391525"
        ixy="1.36625094874662E-07"
        ixz="-9.6682938767263E-08"
        iyy="0.000684347300419342"
        iyz="-6.03575796727363E-08"
        izz="0.000116061793166679" />
    </inertial>
    <visual>
      <origin
        xyz="0 0 0"
        rpy="0 0 0" />
      <geometry>
        <mesh
          filename="package://urdf_leg/meshes/rlink3.STL" />
      </geometry>
      <material
        name="">
        <color
          rgba="0.792156862745098 0.819607843137255 0.933333333333333 1" />
      </material>
    </visual>
    <collision>
      <origin
        xyz="0 0 0"
        rpy="0 0 0" />
      <geometry>
        <mesh
          filename="package://urdf_leg/meshes/rlink3.STL" />
      </geometry>
    </collision>
  </link>
  <joint
    name="rjoint3"
    type="continuous">
    <origin
      xyz="0.00735 -0.44 0"
      rpy="0 0 0" />
    <parent
      link="rlink2" />
    <child
      link="rlink3" />
    <axis
      xyz="1 0 0" />
  </joint>
</robot>